Cannot exec 'one': No such file or directory
 * Serving Flask app "agent003" (lazy loading)
 * Environment: production
[31m   WARNING: Do not use the development server in a production environment.[0m
[2m   Use a production WSGI server instead.[0m
 * Debug mode: off
 * Running on http://0.0.0.0:5000/ (Press CTRL+C to quit)
154.224.202.178 - - [22/Jan/2019 13:03:02] "GET /request/5c1f54de2b5217.19046714/5c1f87c380f2b9.90994146 HTTP/1.1" 200 -
154.224.202.178 - - [22/Jan/2019 13:03:11] "GET /request/5c1f54de2b5217.19046714/5c1f87c380f2b9.90994146 HTTP/1.1" 200 -
154.224.202.178 - - [22/Jan/2019 13:03:14] "GET /request/5c1f54de2b5217.19046714/5c1f87c380f2b9.90994146 HTTP/1.1" 200 -
154.224.202.178 - - [22/Jan/2019 13:03:17] "GET /request/5c1f54de2b5217.19046714/5c1f87c380f2b9.90994146 HTTP/1.1" 200 -
154.224.202.178 - - [22/Jan/2019 13:03:24] "GET /request/5c1f54de2b5217.19046714/5c1f87c380f2b9.90994146 HTTP/1.1" 200 -
154.224.202.178 - - [22/Jan/2019 13:03:43] "GET /request/5c1f54de2b5217.19046714/5c1f87c380f2b9.90994146 HTTP/1.1" 200 -
154.224.202.178 - - [22/Jan/2019 13:03:54] "GET /request/5c1f54de2b5217.19046714/5c1f87c380f2b9.90994146 HTTP/1.1" 200 -
154.224.202.178 - - [22/Jan/2019 13:05:15] "GET /request HTTP/1.1" 404 -
154.224.202.178 - - [22/Jan/2019 13:05:22] "GET /request/edmond HTTP/1.1" 404 -
154.224.202.178 - - [22/Jan/2019 13:05:27] "GET /request/edmond/sylar HTTP/1.1" 200 -
154.224.202.178 - - [22/Jan/2019 13:06:20] "GET /request/edmond/sylar HTTP/1.1" 200 -
154.224.202.178 - - [22/Jan/2019 13:17:42] "GET /request/edmond/sylar HTTP/1.1" 200 -
154.224.202.178 - - [22/Jan/2019 13:20:24] "GET /uploads/eyJ0eXAiOiJKV1QiLCJhbGciOiJIUzI1NiJ9.eyI1YzFmNTRkZTJiNTIxNy4xOTA0NjcxNCI6IjVjMWY4N2MzODBmMmI5LjkwOTk0MTQ2IiwiZXhwIjoxNTQ4MTYyMjM5fQ.FH3DdnGit8cz_VpsE-8vqRu1c5ROwt8wXKiITRwsuRg/dumps.csv HTTP/1.1" 200 -
154.224.202.178 - - [22/Jan/2019 13:45:46] "GET / HTTP/1.1" 200 -
154.224.202.178 - - [22/Jan/2019 13:47:03] "GET / HTTP/1.1" 200 -
154.224.202.178 - - [22/Jan/2019 13:56:34] "GET / HTTP/1.1" 200 -
154.224.202.178 - - [22/Jan/2019 14:10:30] "GET / HTTP/1.1" 200 -
Connected to DB: localhost
File, dumps.csv, has been created successfully
 * Serving Flask app "agent003" (lazy loading)
 * Environment: production
[31m   WARNING: Do not use the development server in a production environment.[0m
[2m   Use a production WSGI server instead.[0m
 * Debug mode: off
 * Running on http://0.0.0.0:5000/ (Press CTRL+C to quit)
154.224.202.178 - - [22/Jan/2019 14:18:37] "GET / HTTP/1.1" 200 -
154.224.202.178 - - [22/Jan/2019 14:21:50] "GET / HTTP/1.1" 200 -
154.224.202.178 - - [22/Jan/2019 14:25:16] "GET /request/5c1f87c380f2b9.90994146/5c1f54de2b5217.19046714 HTTP/1.1" 200 -
154.224.202.178 - - [22/Jan/2019 14:26:46] "GET /request/5c1f54de2b5217.19046714/5c1f87c380f2b9.90994146 HTTP/1.1" 200 -
154.224.202.178 - - [22/Jan/2019 14:27:14] "GET /uploads/eyJ0eXAiOiJKV1QiLCJhbGciOiJIUzI1NiJ9.eyI1YzFmNTRkZTJiNTIxNy4xOTA0NjcxNCI6IjVjMWY4N2MzODBmMmI5LjkwOTk0MTQ2IiwiZXhwIjoxNTQ4MTY3MjExfQ.gC3BX61J8bQ1q04tfveTzaoDGsrf6kYU24Fo0ShVW-c/filers HTTP/1.1" 200 -
107.167.109.163 - - [22/Jan/2019 15:00:25] "GET / HTTP/1.1" 200 -
107.167.109.163 - - [22/Jan/2019 15:00:25] "GET /favicon.ico HTTP/1.1" 404 -
107.167.109.163 - - [22/Jan/2019 15:00:54] "GET /security HTTP/1.1" 200 -
197.239.32.35 - - [22/Jan/2019 16:03:19] "GET / HTTP/1.1" 200 -
197.239.32.35 - - [22/Jan/2019 16:03:20] "GET /favicon.ico HTTP/1.1" 404 -
66.249.81.28 - - [22/Jan/2019 16:10:14] "GET / HTTP/1.1" 200 -
Connected to DB: localhost
File, dumps.csv, has been created successfully
 * Serving Flask app "agent003" (lazy loading)
 * Environment: production
[31m   WARNING: Do not use the development server in a production environment.[0m
[2m   Use a production WSGI server instead.[0m
 * Debug mode: off
 * Running on http://0.0.0.0:5000/ (Press CTRL+C to quit)
66.249.88.22 - - [22/Jan/2019 16:25:02] "GET / HTTP/1.1" 200 -
66.249.88.22 - - [22/Jan/2019 16:25:06] "GET / HTTP/1.1" 200 -
197.239.32.35 - - [22/Jan/2019 16:25:29] "GET /monitor/tasmanianDevil HTTP/1.1" 200 -
197.239.32.35 - - [22/Jan/2019 16:25:33] "GET /monitor/tasmanianDevil HTTP/1.1" 200 -
Connected to DB: localhost
File, dumps.csv, has been created successfully
 * Serving Flask app "agent003" (lazy loading)
 * Environment: production
[31m   WARNING: Do not use the development server in a production environment.[0m
[2m   Use a production WSGI server instead.[0m
 * Debug mode: off
 * Running on http://0.0.0.0:5000/ (Press CTRL+C to quit)
66.249.88.19 - - [22/Jan/2019 16:28:34] "GET /monitor/tasmanianDevil HTTP/1.1" 200 -
154.224.202.178 - - [22/Jan/2019 16:29:00] "GET /monitor/tasman HTTP/1.1" 200 -
154.224.202.178 - - [22/Jan/2019 16:29:06] "GET /monitor/tasmanianDevil HTTP/1.1" 200 -
Connected to DB: localhost
File, dumps.csv, has been created successfully
 * Serving Flask app "agent003" (lazy loading)
 * Environment: production
[31m   WARNING: Do not use the development server in a production environment.[0m
[2m   Use a production WSGI server instead.[0m
 * Debug mode: off
 * Running on http://0.0.0.0:5000/ (Press CTRL+C to quit)
66.249.81.28 - - [22/Jan/2019 16:32:46] "GET /monitor/tasmanianDevil HTTP/1.1" 200 -
Connected to DB: localhost
File, dumps.csv, has been created successfully
 * Serving Flask app "agent003" (lazy loading)
 * Environment: production
[31m   WARNING: Do not use the development server in a production environment.[0m
[2m   Use a production WSGI server instead.[0m
 * Debug mode: off
 * Running on http://0.0.0.0:5000/ (Press CTRL+C to quit)
[2019-01-22 16:36:25,525] ERROR in app: Exception on /monitor/tasmanianDevil [GET]
Traceback (most recent call last):
  File "/root/Astute/privacy/venv/lib/python3.6/site-packages/flask/app.py", line 2292, in wsgi_app
    response = self.full_dispatch_request()
  File "/root/Astute/privacy/venv/lib/python3.6/site-packages/flask/app.py", line 1815, in full_dispatch_request
    rv = self.handle_user_exception(e)
  File "/root/Astute/privacy/venv/lib/python3.6/site-packages/flask/app.py", line 1718, in handle_user_exception
    reraise(exc_type, exc_value, tb)
  File "/root/Astute/privacy/venv/lib/python3.6/site-packages/flask/_compat.py", line 35, in reraise
    raise value
  File "/root/Astute/privacy/venv/lib/python3.6/site-packages/flask/app.py", line 1813, in full_dispatch_request
    rv = self.dispatch_request()
  File "/root/Astute/privacy/venv/lib/python3.6/site-packages/flask/app.py", line 1799, in dispatch_request
    return self.view_functions[rule.endpoint](**req.view_args)
  File "/root/Astute/privacy/Server/views.py", line 45, in admin
    mon = test.monitor()
  File "/root/Astute/privacy/Server/controllers.py", line 98, in monitor
    """.format(len(mon), mon)
KeyError: '\n\t\tmargin'
66.249.81.28 - - [22/Jan/2019 16:36:25] "GET /monitor/tasmanianDevil HTTP/1.1" 500 -
[2019-01-22 16:36:25,986] ERROR in app: Exception on /monitor/tasmanianDevil [GET]
Traceback (most recent call last):
  File "/root/Astute/privacy/venv/lib/python3.6/site-packages/flask/app.py", line 2292, in wsgi_app
    response = self.full_dispatch_request()
  File "/root/Astute/privacy/venv/lib/python3.6/site-packages/flask/app.py", line 1815, in full_dispatch_request
    rv = self.handle_user_exception(e)
  File "/root/Astute/privacy/venv/lib/python3.6/site-packages/flask/app.py", line 1718, in handle_user_exception
    reraise(exc_type, exc_value, tb)
  File "/root/Astute/privacy/venv/lib/python3.6/site-packages/flask/_compat.py", line 35, in reraise
    raise value
  File "/root/Astute/privacy/venv/lib/python3.6/site-packages/flask/app.py", line 1813, in full_dispatch_request
    rv = self.dispatch_request()
  File "/root/Astute/privacy/venv/lib/python3.6/site-packages/flask/app.py", line 1799, in dispatch_request
    return self.view_functions[rule.endpoint](**req.view_args)
  File "/root/Astute/privacy/Server/views.py", line 45, in admin
    mon = test.monitor()
  File "/root/Astute/privacy/Server/controllers.py", line 98, in monitor
    """.format(len(mon), mon)
KeyError: '\n\t\tmargin'
197.239.32.35 - - [22/Jan/2019 16:36:25] "GET /monitor/tasmanianDevil HTTP/1.1" 500 -
[2019-01-22 16:36:30,592] ERROR in app: Exception on /monitor/tasmanianDevil [GET]
Traceback (most recent call last):
  File "/root/Astute/privacy/venv/lib/python3.6/site-packages/flask/app.py", line 2292, in wsgi_app
    response = self.full_dispatch_request()
  File "/root/Astute/privacy/venv/lib/python3.6/site-packages/flask/app.py", line 1815, in full_dispatch_request
    rv = self.handle_user_exception(e)
  File "/root/Astute/privacy/venv/lib/python3.6/site-packages/flask/app.py", line 1718, in handle_user_exception
    reraise(exc_type, exc_value, tb)
  File "/root/Astute/privacy/venv/lib/python3.6/site-packages/flask/_compat.py", line 35, in reraise
    raise value
  File "/root/Astute/privacy/venv/lib/python3.6/site-packages/flask/app.py", line 1813, in full_dispatch_request
    rv = self.dispatch_request()
  File "/root/Astute/privacy/venv/lib/python3.6/site-packages/flask/app.py", line 1799, in dispatch_request
    return self.view_functions[rule.endpoint](**req.view_args)
  File "/root/Astute/privacy/Server/views.py", line 45, in admin
    mon = test.monitor()
  File "/root/Astute/privacy/Server/controllers.py", line 98, in monitor
    """.format(len(mon), mon)
KeyError: '\n\t\tmargin'
66.249.81.26 - - [22/Jan/2019 16:36:30] "GET /monitor/tasmanianDevil HTTP/1.1" 500 -
[2019-01-22 16:36:31,016] ERROR in app: Exception on /monitor/tasmanianDevil [GET]
Traceback (most recent call last):
  File "/root/Astute/privacy/venv/lib/python3.6/site-packages/flask/app.py", line 2292, in wsgi_app
    response = self.full_dispatch_request()
  File "/root/Astute/privacy/venv/lib/python3.6/site-packages/flask/app.py", line 1815, in full_dispatch_request
    rv = self.handle_user_exception(e)
  File "/root/Astute/privacy/venv/lib/python3.6/site-packages/flask/app.py", line 1718, in handle_user_exception
    reraise(exc_type, exc_value, tb)
  File "/root/Astute/privacy/venv/lib/python3.6/site-packages/flask/_compat.py", line 35, in reraise
    raise value
  File "/root/Astute/privacy/venv/lib/python3.6/site-packages/flask/app.py", line 1813, in full_dispatch_request
    rv = self.dispatch_request()
  File "/root/Astute/privacy/venv/lib/python3.6/site-packages/flask/app.py", line 1799, in dispatch_request
    return self.view_functions[rule.endpoint](**req.view_args)
  File "/root/Astute/privacy/Server/views.py", line 45, in admin
    mon = test.monitor()
  File "/root/Astute/privacy/Server/controllers.py", line 98, in monitor
    """.format(len(mon), mon)
KeyError: '\n\t\tmargin'
197.239.32.35 - - [22/Jan/2019 16:36:31] "GET /monitor/tasmanianDevil HTTP/1.1" 500 -
66.249.81.30 - - [22/Jan/2019 16:36:46] "GET / HTTP/1.1" 200 -
66.249.81.30 - - [22/Jan/2019 16:36:48] "GET / HTTP/1.1" 200 -
[2019-01-22 16:36:57,886] ERROR in app: Exception on /monitor/tasmanianDevil [GET]
Traceback (most recent call last):
  File "/root/Astute/privacy/venv/lib/python3.6/site-packages/flask/app.py", line 2292, in wsgi_app
    response = self.full_dispatch_request()
  File "/root/Astute/privacy/venv/lib/python3.6/site-packages/flask/app.py", line 1815, in full_dispatch_request
    rv = self.handle_user_exception(e)
  File "/root/Astute/privacy/venv/lib/python3.6/site-packages/flask/app.py", line 1718, in handle_user_exception
    reraise(exc_type, exc_value, tb)
  File "/root/Astute/privacy/venv/lib/python3.6/site-packages/flask/_compat.py", line 35, in reraise
    raise value
  File "/root/Astute/privacy/venv/lib/python3.6/site-packages/flask/app.py", line 1813, in full_dispatch_request
    rv = self.dispatch_request()
  File "/root/Astute/privacy/venv/lib/python3.6/site-packages/flask/app.py", line 1799, in dispatch_request
    return self.view_functions[rule.endpoint](**req.view_args)
  File "/root/Astute/privacy/Server/views.py", line 45, in admin
    mon = test.monitor()
  File "/root/Astute/privacy/Server/controllers.py", line 98, in monitor
    """.format(len(mon), mon)
KeyError: '\n\t\tmargin'
66.249.81.28 - - [22/Jan/2019 16:36:57] "GET /monitor/tasmanianDevil HTTP/1.1" 500 -
[2019-01-22 16:36:58,370] ERROR in app: Exception on /monitor/tasmanianDevil [GET]
Traceback (most recent call last):
  File "/root/Astute/privacy/venv/lib/python3.6/site-packages/flask/app.py", line 2292, in wsgi_app
    response = self.full_dispatch_request()
  File "/root/Astute/privacy/venv/lib/python3.6/site-packages/flask/app.py", line 1815, in full_dispatch_request
    rv = self.handle_user_exception(e)
  File "/root/Astute/privacy/venv/lib/python3.6/site-packages/flask/app.py", line 1718, in handle_user_exception
    reraise(exc_type, exc_value, tb)
  File "/root/Astute/privacy/venv/lib/python3.6/site-packages/flask/_compat.py", line 35, in reraise
    raise value
  File "/root/Astute/privacy/venv/lib/python3.6/site-packages/flask/app.py", line 1813, in full_dispatch_request
    rv = self.dispatch_request()
  File "/root/Astute/privacy/venv/lib/python3.6/site-packages/flask/app.py", line 1799, in dispatch_request
    return self.view_functions[rule.endpoint](**req.view_args)
  File "/root/Astute/privacy/Server/views.py", line 45, in admin
    mon = test.monitor()
  File "/root/Astute/privacy/Server/controllers.py", line 98, in monitor
    """.format(len(mon), mon)
KeyError: '\n\t\tmargin'
197.239.32.35 - - [22/Jan/2019 16:36:58] "GET /monitor/tasmanianDevil HTTP/1.1" 500 -
Connected to DB: localhost
File, dumps.csv, has been created successfully
 * Serving Flask app "agent003" (lazy loading)
 * Environment: production
[31m   WARNING: Do not use the development server in a production environment.[0m
[2m   Use a production WSGI server instead.[0m
 * Debug mode: off
 * Running on http://0.0.0.0:5000/ (Press CTRL+C to quit)
[2019-01-22 16:37:27,821] ERROR in app: Exception on /monitor/tasmanianDevil [GET]
Traceback (most recent call last):
  File "/root/Astute/privacy/venv/lib/python3.6/site-packages/flask/app.py", line 2292, in wsgi_app
    response = self.full_dispatch_request()
  File "/root/Astute/privacy/venv/lib/python3.6/site-packages/flask/app.py", line 1815, in full_dispatch_request
    rv = self.handle_user_exception(e)
  File "/root/Astute/privacy/venv/lib/python3.6/site-packages/flask/app.py", line 1718, in handle_user_exception
    reraise(exc_type, exc_value, tb)
  File "/root/Astute/privacy/venv/lib/python3.6/site-packages/flask/_compat.py", line 35, in reraise
    raise value
  File "/root/Astute/privacy/venv/lib/python3.6/site-packages/flask/app.py", line 1813, in full_dispatch_request
    rv = self.dispatch_request()
  File "/root/Astute/privacy/venv/lib/python3.6/site-packages/flask/app.py", line 1799, in dispatch_request
    return self.view_functions[rule.endpoint](**req.view_args)
  File "/root/Astute/privacy/Server/views.py", line 45, in admin
    mon = test.monitor()
  File "/root/Astute/privacy/Server/controllers.py", line 93, in monitor
    """.format(len(mon), mon)
KeyError: '\n\t\tmargin'
66.249.81.30 - - [22/Jan/2019 16:37:27] "GET /monitor/tasmanianDevil HTTP/1.1" 500 -
[2019-01-22 16:37:28,312] ERROR in app: Exception on /monitor/tasmanianDevil [GET]
Traceback (most recent call last):
  File "/root/Astute/privacy/venv/lib/python3.6/site-packages/flask/app.py", line 2292, in wsgi_app
    response = self.full_dispatch_request()
  File "/root/Astute/privacy/venv/lib/python3.6/site-packages/flask/app.py", line 1815, in full_dispatch_request
    rv = self.handle_user_exception(e)
  File "/root/Astute/privacy/venv/lib/python3.6/site-packages/flask/app.py", line 1718, in handle_user_exception
    reraise(exc_type, exc_value, tb)
  File "/root/Astute/privacy/venv/lib/python3.6/site-packages/flask/_compat.py", line 35, in reraise
    raise value
  File "/root/Astute/privacy/venv/lib/python3.6/site-packages/flask/app.py", line 1813, in full_dispatch_request
    rv = self.dispatch_request()
  File "/root/Astute/privacy/venv/lib/python3.6/site-packages/flask/app.py", line 1799, in dispatch_request
    return self.view_functions[rule.endpoint](**req.view_args)
  File "/root/Astute/privacy/Server/views.py", line 45, in admin
    mon = test.monitor()
  File "/root/Astute/privacy/Server/controllers.py", line 93, in monitor
    """.format(len(mon), mon)
KeyError: '\n\t\tmargin'
197.239.32.35 - - [22/Jan/2019 16:37:28] "GET /monitor/tasmanianDevil HTTP/1.1" 500 -
66.249.81.30 - - [22/Jan/2019 16:37:35] "GET / HTTP/1.1" 200 -
Connected to DB: localhost
File, dumps.csv, has been created successfully
 * Serving Flask app "agent003" (lazy loading)
 * Environment: production
[31m   WARNING: Do not use the development server in a production environment.[0m
[2m   Use a production WSGI server instead.[0m
 * Debug mode: off
 * Running on http://0.0.0.0:5000/ (Press CTRL+C to quit)
66.249.81.28 - - [22/Jan/2019 16:38:24] "GET / HTTP/1.1" 200 -
66.249.81.28 - - [22/Jan/2019 16:38:24] "GET / HTTP/1.1" 200 -
[2019-01-22 16:38:32,898] ERROR in app: Exception on /monitor/tasmanianDevil [GET]
Traceback (most recent call last):
  File "/root/Astute/privacy/venv/lib/python3.6/site-packages/flask/app.py", line 2292, in wsgi_app
    response = self.full_dispatch_request()
  File "/root/Astute/privacy/venv/lib/python3.6/site-packages/flask/app.py", line 1815, in full_dispatch_request
    rv = self.handle_user_exception(e)
  File "/root/Astute/privacy/venv/lib/python3.6/site-packages/flask/app.py", line 1718, in handle_user_exception
    reraise(exc_type, exc_value, tb)
  File "/root/Astute/privacy/venv/lib/python3.6/site-packages/flask/_compat.py", line 35, in reraise
    raise value
  File "/root/Astute/privacy/venv/lib/python3.6/site-packages/flask/app.py", line 1813, in full_dispatch_request
    rv = self.dispatch_request()
  File "/root/Astute/privacy/venv/lib/python3.6/site-packages/flask/app.py", line 1799, in dispatch_request
    return self.view_functions[rule.endpoint](**req.view_args)
  File "/root/Astute/privacy/Server/views.py", line 45, in admin
    mon = test.monitor()
  File "/root/Astute/privacy/Server/controllers.py", line 95, in monitor
    """.format(len(mon), mon)
KeyError: '\n\t\tmargin'
66.249.81.30 - - [22/Jan/2019 16:38:32] "GET /monitor/tasmanianDevil HTTP/1.1" 500 -
[2019-01-22 16:38:33,385] ERROR in app: Exception on /monitor/tasmanianDevil [GET]
Traceback (most recent call last):
  File "/root/Astute/privacy/venv/lib/python3.6/site-packages/flask/app.py", line 2292, in wsgi_app
    response = self.full_dispatch_request()
  File "/root/Astute/privacy/venv/lib/python3.6/site-packages/flask/app.py", line 1815, in full_dispatch_request
    rv = self.handle_user_exception(e)
  File "/root/Astute/privacy/venv/lib/python3.6/site-packages/flask/app.py", line 1718, in handle_user_exception
    reraise(exc_type, exc_value, tb)
  File "/root/Astute/privacy/venv/lib/python3.6/site-packages/flask/_compat.py", line 35, in reraise
    raise value
  File "/root/Astute/privacy/venv/lib/python3.6/site-packages/flask/app.py", line 1813, in full_dispatch_request
    rv = self.dispatch_request()
  File "/root/Astute/privacy/venv/lib/python3.6/site-packages/flask/app.py", line 1799, in dispatch_request
    return self.view_functions[rule.endpoint](**req.view_args)
  File "/root/Astute/privacy/Server/views.py", line 45, in admin
    mon = test.monitor()
  File "/root/Astute/privacy/Server/controllers.py", line 95, in monitor
    """.format(len(mon), mon)
KeyError: '\n\t\tmargin'
197.239.32.35 - - [22/Jan/2019 16:38:33] "GET /monitor/tasmanianDevil HTTP/1.1" 500 -
Connected to DB: localhost
File, dumps.csv, has been created successfully
 * Serving Flask app "agent003" (lazy loading)
 * Environment: production
[31m   WARNING: Do not use the development server in a production environment.[0m
[2m   Use a production WSGI server instead.[0m
 * Debug mode: off
 * Running on http://0.0.0.0:5000/ (Press CTRL+C to quit)
66.249.81.26 - - [22/Jan/2019 16:39:57] "GET / HTTP/1.1" 200 -
66.249.81.28 - - [22/Jan/2019 16:40:04] "GET /monitor/tasmanianDevil HTTP/1.1" 200 -
154.224.202.178 - - [22/Jan/2019 16:40:59] "GET /monitor/tasmanianDevil HTTP/1.1" 200 -
Connected to DB: localhost
File, dumps.csv, has been created successfully
 * Serving Flask app "agent003" (lazy loading)
 * Environment: production
[31m   WARNING: Do not use the development server in a production environment.[0m
[2m   Use a production WSGI server instead.[0m
 * Debug mode: off
 * Running on http://0.0.0.0:5000/ (Press CTRL+C to quit)
197.239.32.35 - - [22/Jan/2019 16:42:06] "GET /monitor/tasmanianDevil HTTP/1.1" 200 -
Connected to DB: localhost
File, dumps.csv, has been created successfully
 * Serving Flask app "agent003" (lazy loading)
 * Environment: production
[31m   WARNING: Do not use the development server in a production environment.[0m
[2m   Use a production WSGI server instead.[0m
 * Debug mode: off
 * Running on http://0.0.0.0:5000/ (Press CTRL+C to quit)
197.239.32.35 - - [22/Jan/2019 16:42:47] "GET /monitor/tasmanianDevil HTTP/1.1" 200 -
66.249.81.28 - - [22/Jan/2019 16:44:03] "GET /monitor/tasmanianDevil HTTP/1.1" 200 -
66.249.81.28 - - [22/Jan/2019 16:44:11] "GET /monitor/tasmanianDevil HTTP/1.1" 200 -
Connected to DB: localhost
File, dumps.csv, has been created successfully
 * Serving Flask app "agent003" (lazy loading)
 * Environment: production
[31m   WARNING: Do not use the development server in a production environment.[0m
[2m   Use a production WSGI server instead.[0m
 * Debug mode: off
 * Running on http://0.0.0.0:5000/ (Press CTRL+C to quit)
102.87.90.138 - - [23/Jan/2019 10:46:57] "GET /monitor/tasmanianDevil HTTP/1.1" 200 -
102.87.90.138 - - [23/Jan/2019 10:46:58] "GET /favicon.ico HTTP/1.1" 404 -
102.87.90.138 - - [23/Jan/2019 10:47:59] "GET /server/server_arrange/drastic_changez__ HTTP/1.1" 404 -
66.249.81.20 - - [23/Jan/2019 10:48:14] "GET /server/auth/server_arrange/drastic_changez__ HTTP/1.1" 200 -
Traceback (most recent call last):
  File "agent003.py", line 6, in <module>
    from views import *
  File "/root/Astute/privacy/Server/views.py", line 60
    result_set = 'Proceeded Successfully'
                                        ^
TabError: inconsistent use of tabs and spaces in indentation
Traceback (most recent call last):
  File "agent003.py", line 6, in <module>
    from views import *
  File "/root/Astute/privacy/Server/views.py", line 60
    result_set = 'Proceeded Successfully'
                                        ^
TabError: inconsistent use of tabs and spaces in indentation
Connected to DB: localhost
File, dumps.csv, has been created successfully
 * Serving Flask app "agent003" (lazy loading)
 * Environment: production
[31m   WARNING: Do not use the development server in a production environment.[0m
[2m   Use a production WSGI server instead.[0m
 * Debug mode: off
 * Running on http://0.0.0.0:5000/ (Press CTRL+C to quit)
102.87.90.138 - - [23/Jan/2019 11:09:57] "GET /server/server_arrange/drastic_changez__ HTTP/1.1" 404 -
66.249.81.22 - - [23/Jan/2019 11:10:14] "GET / HTTP/1.1" 200 -
102.87.90.138 - - [23/Jan/2019 11:10:17] "GET / HTTP/1.1" 200 -
66.249.81.28 - - [23/Jan/2019 11:41:07] "GET /monitor/tasmanianDevil HTTP/1.1" 200 -
66.249.81.30 - - [23/Jan/2019 11:41:26] "GET /monitor/tasmanianDevil HTTP/1.1" 200 -
207.154.213.196 - - [23/Jan/2019 12:16:26] "GET / HTTP/1.1" 200 -
